Workbook

Sheet Read Me
A1: SOC 2 Type II – Control Matrix & Evidence Tracker
A2: Scope: Security (Common Criteria CC1–CC9), AICPA 2017 Trust Services Criteria with Revised Points of Focus (2022). Tailored for GitHub Enterprise Cloud, GitHub Actions and ServiceNow; other subsystems vendor-neutral pending the Info Request.
A4: Organization | B4: [Company Name]
A5: System in scope | B5: [System / Product Name]
A6: Observation period | B6: [Start date] – [End date] (typically 3–12 months)
A7: Document owner | B7: [Compliance Manager]
A8: Version / date | B8: v1.1 – [Date] (GitHub / GitHub Actions / ServiceNow tailoring)
A10: HOW TO USE
A11: Yellow cells | B11: Fill-in fields. Replace placeholders and complete Named Owner, Tool Implemented, Status, Last Tested and PBC status columns.
A12: Blue italic text | B12: Example values showing expected format – overwrite with your own.
A13: Readiness Dashboard | B13: Calculated from Implementation Status in the Control Matrix. Do not edit – formulas.
A14: Control Matrix | B14: 69 controls mapped to all 33 Common Criteria. Each row lists subsystems, owner role, frequency, evidence, automation approach and Type II test procedure.
A15: TSC Coverage | B15: One row per Common Criterion with count of mapped controls (formula) and readiness status. Any 'GAP' must be resolved before fieldwork.
A16: Integration Inventory | B16: In-scope subsystems, how each integrates with the IdP, log pipeline and other subsystems, and what evidence it produces.
A17: Evidence Automation | B17: Scheduled collector jobs that pull evidence via API into the immutable evidence store.
A18: PBC Evidence List | B18: 'Provided By Client' request list – what the auditor will ask for, per control. Track status here during fieldwork.
A19: Risk Register | B19: Seed risk register with inherent/residual scoring (Likelihood × Impact, 1–5 scale). Adjust to your environment.
A20: Compliance Calendar | B20: Recurring control activities across the 12 months of the observation period (M1 = first month).
A21: GitHub-ServiceNow Config | B21: Required configuration settings for GitHub Enterprise Cloud, GitHub Actions and ServiceNow, how to verify each (API/UI), and the control it supports. Track status in the yellow columns.
A22: Info Request | B22: Questions to answer for the remaining subsystems (and open decisions on GitHub/ServiceNow) so the package can be fully tailored.
... A25: Important | B25: This is a template. Control descriptions must reflect what you actually do; auditors test the controls as written. Remove or edit any control you do not operate, and re-check TSC Coverage afterwards.

Sheet Info Request
A1: # | B1: Area | C1: Subsystem | D1: Question | E1: Why It's Needed | F1: Controls Affected | G1: Answer | H1: Answered By / Date
A2: 1 | B2: Organization | C2: General | D2: Legal entity name, system/product name, and a one-paragraph description of the service | E2: System description (SYS-001 §1) | F2: GOV-08
A3: 2 | B3: Organization | C3: General | D3: Headcount (employees/contractors) and org chart for Security, Platform/SRE, IT, Engineering | E3: People section; RACI; owners | F3: GOV-03
A4: 3 | B4: Organization | C4: General | D4: Target observation period (start date, length) and audit firm (if selected) | E4: Calendar, sampling, readiness plan | F4: GOV-05
A5: 4 | B5: Organization | C5: General | D5: Customer data types processed (PII? payment? health?) and hosting regions | E5: Classification, encryption, CUECs | F5: INF-05, POL-09
A6: 5 | B6: Organization | C6: General | D6: Existing policies, prior audits/pen tests, or known gaps | E6: Avoid duplication; gap analysis | F6: GOV-01
A7: 6 | B7: GitHub | C7: SCM | D7: Q1: GitHub Enterprise Cloud with EMU, Enterprise Cloud with SAML (personal accounts), or Enterprise Server (version)? | E7: Identity, SCIM, audit-log design | F7: IAM-01, IAM-03, MON-01
A8: 7 | B8: GitHub | C8: SCM | D8: Q2: Are GitHub Secret Protection and Code Security licensed for all in-scope repos? | E8: Else third-party SAST/SCA/secret scanners | F8: CHG-04, INF-06
A9: 8 | B9: GitHub | C9: SCM | D9: Q6: Number of GitHub organizations and in-scope repositories (list or estimate) | E9: Ruleset scope; populations | F9: CHG-01, GOV-08
A10: 9 | B10: GitHub | C10: SCM | D10: Is there a monorepo, and are any production repos public? | E10: Ruleset and fork settings | F10: CHG-01, INF-11
A11: 10 | B11: GitHub Actions | C11: CI | D11: Q3: GitHub-hosted, self-hosted, or both runners? If self-hosted: platform (ARC/Kubernetes, VMs) and network location | E11: Runner hardening; prod network path | F11: CHG-11
A12: 11 | B12: GitHub Actions | C12: CI | D12: Q7: Where are artifacts/images stored (GHCR/GitHub Packages or cloud registry)? | E12: Attestation and admission design | F12: CHG-07
A13: 12 | B13: GitHub Actions | C13: CI | D13: Q8: Any production deploys outside GitHub Actions today (manual, scripts, other CD tools e.g. Argo CD)? | E13: Must be brought under the gate before period start | F13: CHG-05
... A35: 34 | B35: Vendors | C35: VEN | D35: List of vendors with access to customer data or production (sub-service organizations) | E35: Carve-outs, CSOCs, VEN controls | F35: VEN-01, VEN-02
D37: Answered | E37: =COUNTA(G2:G35)&" of "&COUNTA(D2:D35) -> 0 of 34

Sheet Readiness Dashboard
A1: Readiness Dashboard
A2: All values are formulas driven by 'Control Matrix' column R (Implementation Status).
A4: Domain | B4: Controls | C4: Implemented | D4: Partial | E4: Not impl. | F4: N/A | G4: % Implemented
A5: Governance | B5: =COUNTIF('Control Matrix'!$B$2:$B$70,A5) -> 8 | C5: =COUNTIFS('Control Matrix'!$B$2:$B$70,A5,'Control Matrix'!$R$2:$R$70,"Implemented") -> 1 | D5: =COUNTIFS('Control Matrix'!$B$2:$B$70,A5,'Control Matrix'!$R$2:$R$70,"Partially implemented") -> 0 | E5: =COUNTIFS('Control Matrix'!$B$2:$B$70,A5,'Control Matrix'!$R$2:$R$70,"Not implemented") -> 0 | F5: =COUNTIFS('Control Matrix'!$B$2:$B$70,A5,'Control Matrix'!$R$2:$R$70,"Not applicable") -> 0 | G5: =IF((B5-F5)=0,0,C5/(B5-F5)) -> 0.125
A6: Human Resources | B6: =COUNTIF('Control Matrix'!$B$2:$B$70,A6) -> 5 | C6: =COUNTIFS('Control Matrix'!$B$2:$B$70,A6,'Control Matrix'!$R$2:$R$70,"Implemented") -> 0 | D6: =COUNTIFS('Control Matrix'!$B$2:$B$70,A6,'Control Matrix'!$R$2:$R$70,"Partially implemented") -> 0 | E6: =COUNTIFS('Control Matrix'!$B$2:$B$70,A6,'Control Matrix'!$R$2:$R$70,"Not implemented") -> 0 | F6: =COUNTIFS('Control Matrix'!$B$2:$B$70,A6,'Control Matrix'!$R$2:$R$70,"Not applicable") -> 0 | G6: =IF((B6-F6)=0,0,C6/(B6-F6)) -> 0
A7: Risk Management | B7: =COUNTIF('Control Matrix'!$B$2:$B$70,A7) -> 4 | C7: =COUNTIFS('Control Matrix'!$B$2:$B$70,A7,'Control Matrix'!$R$2:$R$70,"Implemented") -> 0 | D7: =COUNTIFS('Control Matrix'!$B$2:$B$70,A7,'Control Matrix'!$R$2:$R$70,"Partially implemented") -> 0 | E7: =COUNTIFS('Control Matrix'!$B$2:$B$70,A7,'Control Matrix'!$R$2:$R$70,"Not implemented") -> 0 | F7: =COUNTIFS('Control Matrix'!$B$2:$B$70,A7,'Control Matrix'!$R$2:$R$70,"Not applicable") -> 0 | G7: =IF((B7-F7)=0,0,C7/(B7-F7)) -> 0
A8: Vendor Management | B8: =COUNTIF('Control Matrix'!$B$2:$B$70,A8) -> 3 | C8: =COUNTIFS('Control Matrix'!$B$2:$B$70,A8,'Control Matrix'!$R$2:$R$70,"Implemented") -> 0 | D8: =COUNTIFS('Control Matrix'!$B$2:$B$70,A8,'Control Matrix'!$R$2:$R$70,"Partially implemented") -> 0 | E8: =COUNTIFS('Control Matrix'!$B$2:$B$70,A8,'Control Matrix'!$R$2:$R$70,"Not implemented") -> 0 | F8: =COUNTIFS('Control Matrix'!$B$2:$B$70,A8,'Control Matrix'!$R$2:$R$70,"Not applicable") -> 0 | G8: =IF((B8-F8)=0,0,C8/(B8-F8)) -> 0
A9: Identity & Access | B9: =COUNTIF('Control Matrix'!$B$2:$B$70,A9) -> 9 | C9: =COUNTIFS('Control Matrix'!$B$2:$B$70,A9,'Control Matrix'!$R$2:$R$70,"Implemented") -> 0 | D9: =COUNTIFS('Control Matrix'!$B$2:$B$70,A9,'Control Matrix'!$R$2:$R$70,"Partially implemented") -> 0 | E9: =COUNTIFS('Control Matrix'!$B$2:$B$70,A9,'Control Matrix'!$R$2:$R$70,"Not implemented") -> 0 | F9: =COUNTIFS('Control Matrix'!$B$2:$B$70,A9,'Control Matrix'!$R$2:$R$70,"Not applicable") -> 0 | G9: =IF((B9-F9)=0,0,C9/(B9-F9)) -> 0
A10: Change Management | B10: =COUNTIF('Control Matrix'!$B$2:$B$70,A10) -> 12 | C10: =COUNTIFS('Control Matrix'!$B$2:$B$70,A10,'Control Matrix'!$R$2:$R$70,"Implemented") -> 0 | D10: =COUNTIFS('Control Matrix'!$B$2:$B$70,A10,'Control Matrix'!$R$2:$R$70,"Partially implemented") -> 0 | E10: =COUNTIFS('Control Matrix'!$B$2:$B$70,A10,'Control Matrix'!$R$2:$R$70,"Not implemented") -> 0 | F10: =COUNTIFS('Control Matrix'!$B$2:$B$70,A10,'Control Matrix'!$R$2:$R$70,"Not applicable") -> 0 | G10: =IF((B10-F10)=0,0,C10/(B10-F10)) -> 0
A11: Infrastructure | B11: =COUNTIF('Control Matrix'!$B$2:$B$70,A11) -> 11 | C11: =COUNTIFS('Control Matrix'!$B$2:$B$70,A11,'Control Matrix'!$R$2:$R$70,"Implemented") -> 0 | D11: =COUNTIFS('Control Matrix'!$B$2:$B$70,A11,'Control Matrix'!$R$2:$R$70,"Partially implemented") -> 0 | E11: =COUNTIFS('Control Matrix'!$B$2:$B$70,A11,'Control Matrix'!$R$2:$R$70,"Not implemented") -> 0 | F11: =COUNTIFS('Control Matrix'!$B$2:$B$70,A11,'Control Matrix'!$R$2:$R$70,"Not applicable") -> 0 | G11: =IF((B11-F11)=0,0,C11/(B11-F11)) -> 0
A12: Vulnerability Management | B12: =COUNTIF('Control Matrix'!$B$2:$B$70,A12) -> 3 | C12: =COUNTIFS('Control Matrix'!$B$2:$B$70,A12,'Control Matrix'!$R$2:$R$70,"Implemented") -> 0 | D12: =COUNTIFS('Control Matrix'!$B$2:$B$70,A12,'Control Matrix'!$R$2:$R$70,"Partially implemented") -> 0 | E12: =COUNTIFS('Control Matrix'!$B$2:$B$70,A12,'Control Matrix'!$R$2:$R$70,"Not implemented") -> 0 | F12: =COUNTIFS('Control Matrix'!$B$2:$B$70,A12,'Control Matrix'!$R$2:$R$70,"Not applicable") -> 0 | G12: =IF((B12-F12)=0,0,C12/(B12-F12)) -> 0
A13: Logging & Monitoring | B13: =COUNTIF('Control Matrix'!$B$2:$B$70,A13) -> 6 | C13: =COUNTIFS('Control Matrix'!$B$2:$B$70,A13,'Control Matrix'!$R$2:$R$70,"Implemented") -> 0 | D13: =COUNTIFS('Control Matrix'!$B$2:$B$70,A13,'Control Matrix'!$R$2:$R$70,"Partially implemented") -> 0 | E13: =COUNTIFS('Control Matrix'!$B$2:$B$70,A13,'Control Matrix'!$R$2:$R$70,"Not implemented") -> 0 | F13: =COUNTIFS('Control Matrix'!$B$2:$B$70,A13,'Control Matrix'!$R$2:$R$70,"Not applicable") -> 0 | G13: =IF((B13-F13)=0,0,C13/(B13-F13)) -> 0
A14: Incident Response | B14: =COUNTIF('Control Matrix'!$B$2:$B$70,A14) -> 4 | C14: =COUNTIFS('Control Matrix'!$B$2:$B$70,A14,'Control Matrix'!$R$2:$R$70,"Implemented") -> 0 | D14: =COUNTIFS('Control Matrix'!$B$2:$B$70,A14,'Control Matrix'!$R$2:$R$70,"Partially implemented") -> 0 | E14: =COUNTIFS('Control Matrix'!$B$2:$B$70,A14,'Control Matrix'!$R$2:$R$70,"Not implemented") -> 0 | F14: =COUNTIFS('Control Matrix'!$B$2:$B$70,A14,'Control Matrix'!$R$2:$R$70,"Not applicable") -> 0 | G14: =IF((B14-F14)=0,0,C14/(B14-F14)) -> 0
A15: Business Continuity | B15: =COUNTIF('Control Matrix'!$B$2:$B$70,A15) -> 4 | C15: =COUNTIFS('Control Matrix'!$B$2:$B$70,A15,'Control Matrix'!$R$2:$R$70,"Implemented") -> 0 | D15: =COUNTIFS('Control Matrix'!$B$2:$B$70,A15,'Control Matrix'!$R$2:$R$70,"Partially implemented") -> 0 | E15: =COUNTIFS('Control Matrix'!$B$2:$B$70,A15,'Control Matrix'!$R$2:$R$70,"Not implemented") -> 0 | F15: =COUNTIFS('Control Matrix'!$B$2:$B$70,A15,'Control Matrix'!$R$2:$R$70,"Not applicable") -> 0 | G15: =IF((B15-F15)=0,0,C15/(B15-F15)) -> 0
A16: TOTAL | B16: =SUM(B5:B15) -> 69 | C16: =SUM(C5:C15) -> 1 | D16: =SUM(D5:D15) -> 0 | E16: =SUM(E5:E15) -> 0 | F16: =SUM(F5:F15) -> 0 | G16: =IF((B16-F16)=0,0,C16/(B16-F16)) -> 0.014492754
A18: Criteria coverage
A19: Common Criteria in scope | B19: =COUNTA('TSC Coverage'!A2:A34) -> 33
A20: Criteria with design GAP | B20: =COUNTIF('TSC Coverage'!F2:F34,"GAP") -> 0
A21: Criteria fully ready | B21: =COUNTIF('TSC Coverage'!G2:G34,"Ready") -> 1
A22: PBC items received | B22: =COUNTIF('PBC Evidence List'!I:I,"Received")+COUNTIF('PBC Evidence List'!I:I,"Accepted") -> 0
A23: PBC items total | B23: =COUNTA('PBC Evidence List'!A:A)-1 -> 135
A24: Residual risks rated Medium/High (score ≥ 8) | B24: =COUNTIF('Risk Register'!K2:K200,">=8") -> 2

Sheet Control Matrix
A1: Control ID | B1: Domain | C1: Control Title | D1: Control Description | E1: Subsystems | F1: Control Type | G1: Nature | H1: Frequency | I1: Owner (Role) | J1: TSC Mapping | K1: Evidence Required | L1: Evidence Automation | M1: Type II Test Procedure | N1: Sampling Basis | O1: Min. Sample | P1: Named Owner | Q1: Tool / System Implemented | R1: Implementation Status | S1: Last Tested | T1: Notes
A2: GOV-01 | B2: Governance | C2: Security policies approved and published | D2: Information security policies are reviewed at least annually, approved by executive management, version-controlled, and published to all personnel. | E2: GRC | F2: Preventive | G2: Manual | H2: Annual | I2: CISO / Security Lead | J2: CC1.1, CC2.2, CC5.3 | K2: Policy set with version history and approval record; publication location screenshot | L2: Policies stored as code in a policy repo; approval via PR review is captured automatically | M2: 1) Inquire of CISO / Security Lead. 2) Obtain the complete population of occurrences for the period and verify completeness (system-generated list). 3) Select a sample per the Sampling Guide. 4) Inspect evidence (Policy set with version history and approval record) for performance, timeliness, reviewer independence and follow-up of exceptions. | N2: Annual | O2: =IFERROR(INDEX('Sampling Guide'!$B$2:$B$20,MATCH(N2,'Sampling Guide'!$A$2:$A$20,0)),"TBD") -> 1 | P2: Jane Doe | Q2: e.g., GitHub policy repo + ServiceNow approval | R2: Implemented | S2: 2026-01-15 | T2: Example row – overwrite
A3: GOV-02 | B3: Governance | C3: Board / oversight committee security review | D3: The Board (or an oversight committee independent of management) receives a security and compliance update at least annually, including risk assessment results and control deficiencies. | E3: GRC | F3: Detective | G3: Manual | H3: Annual | I3: CEO | J3: CC1.2, CC4.2 | K3: Board / committee meeting minutes and presentation deck | L3: Manual upload to evidence store | M3: 1) Inquire of CEO. 2) Obtain the complete population of occurrences for the period and verify completeness (system-generated list). 3) Select a sample per the Sampling Guide. 4) Inspect evidence (Board / committee meeting minutes and presentation deck) for performance, timeliness, reviewer independence and follow-up of exceptions. | N3: Annual | O3: =IFERROR(INDEX('Sampling Guide'!$B$2:$B$20,MATCH(N3,'Sampling Guide'!$A$2:$A$20,0)),"TBD") -> 1
A4: GOV-03 | B4: Governance | C4: Organization chart and security roles defined | D4: An organization chart and a RACI of security and compliance responsibilities are maintained and reviewed annually. | E4: HRIS, GRC | F4: Preventive | G4: IT-dependent manual | H4: Annual | I4: Head of People | J4: CC1.3 | K4: Org chart export; RACI document with review date | L4: Org chart exported from HRIS by scheduled job | M4: 1) Inquire of Head of People. 2) Obtain the complete population of occurrences for the period and verify completeness (system-generated list). 3) Select a sample per the Sampling Guide. 4) Inspect evidence (Org chart export) for performance, timeliness, reviewer independence and follow-up of exceptions. | N4: Annual | O4: =IFERROR(INDEX('Sampling Guide'!$B$2:$B$20,MATCH(N4,'Sampling Guide'!$A$2:$A$20,0)),"TBD") -> 1
A5: GOV-04 | B5: Governance | C5: Security and compliance steering meeting | D5: A security steering group meets at least quarterly to review metrics, open risks, audit status and control failures; actions are tracked to closure. | E5: ITSM, GRC | F5: Detective | G5: Manual | H5: Quarterly | I5: CISO / Security Lead | J5: CC1.3, CC2.1, CC4.1, CC4.2 | K5: Meeting agendas, minutes and action tracker | L5: Action items tracked as tickets with label 'sec-steering' | M5: 1) Inquire of CISO / Security Lead. 2) Obtain the complete population of occurrences for the period and verify completeness (system-generated list). 3) Select a sample per the Sampling Guide. 4) Inspect evidence (Meeting agendas, minutes and action tracker) for performance, timeliness, reviewer independence and follow-up of exceptions. | N5: Quarterly | O5: =IFERROR(INDEX('Sampling Guide'!$B$2:$B$20,MATCH(N5,'Sampling Guide'!$A$2:$A$20,0)),"TBD") -> 2 | Q5: Action items tracked as ServiceNow tasks
A6: GOV-05 | B6: Governance | C6: Internal control self-assessment | D6: Control owners attest quarterly that their controls operated; the compliance function performs an annual internal assessment and tracks deficiencies to remediation. | E6: GRC, ITSM | F6: Detective | G6: IT-dependent manual | H6: Quarterly | I6: Compliance Manager | J6: CC4.1, CC4.2, CC5.1 | K6: Quarterly attestations; internal assessment report; deficiency tickets | L6: Automated control-health dashboard fed by evidence collectors | M6: 1) Inquire of Compliance Manager. 2) Obtain the complete population of occurrences for the period and verify completeness (system-generated list). 3) Select a sample per the Sampling Guide. 4) Inspect evidence (Quarterly attestations) for performance, timeliness, reviewer independence and follow-up of exceptions. | N6: Quarterly | O6: =IFERROR(INDEX('Sampling Guide'!$B$2:$B$20,MATCH(N6,'Sampling Guide'!$A$2:$A$20,0)),"TBD") -> 2
A7: GOV-06 | B7: Governance | C7: External communication of commitments | D7: Security commitments, system changes affecting customers, and incident notifications are communicated through contracts, the trust/status page and customer notices. | E7: GRC | F7: Preventive | G7: Manual | H7: Ongoing | I7: Legal / Compliance | J7: CC2.3 | K7: MSA/DPA templates; status page history; customer notices | L7: Status page history export | M7: 1) Inquire of Legal / Compliance. 2) Obtain the complete population of occurrences for the period and verify completeness (system-generated list). 3) Select a sample per the Sampling Guide. 4) Inspect evidence (MSA/DPA templates) for performance, timeliness, reviewer independence and follow-up of exceptions. | N7: Per event / multiple times per day | O7: =IFERROR(INDEX('Sampling Guide'!$B$2:$B$20,MATCH(N7,'Sampling Guide'!$A$2:$A$20,0)),"TBD") -> 25
A8: GOV-07 | B8: Governance | C8: Whistleblower / reporting channel | D8: An anonymous channel exists for personnel and external parties to report security concerns, fraud or ethics violations; reports are triaged and tracked. | E8: ITSM | F8: Detective | G8: Manual | H8: Ongoing | I8: Legal / Compliance | J8: CC1.1, CC2.2, CC2.3 | K8: Channel description in handbook; report log (redacted) | L8: n/a | M8: 1) Inquire of Legal / Compliance. 2) Obtain the complete population of occurrences for the period and verify completeness (system-generated list). 3) Select a sample per the Sampling Guide. 4) Inspect evidence (Channel description in handbook) for performance, timeliness, reviewer independence and follow-up of exceptions. | N8: Per event / multiple times per day | O8: =IFERROR(INDEX('Sampling Guide'!$B$2:$B$20,MATCH(N8,'Sampling Guide'!$A$2:$A$20,0)),"TBD") -> 25
A9: GOV-08 | B9: Governance | C9: System description and boundaries maintained | D9: The in-scope system description, data-flow diagrams and subsystem inventory are reviewed and updated at least annually and upon significant change. | E9: GRC, CLD | F9: Preventive | G9: IT-dependent manual | H9: Annual | I9: Compliance Manager | J9: CC2.1, CC3.4 | K9: Dated system description; architecture diagrams; integration inventory | L9: Cloud asset inventory export attached to review | M9: 1) Inquire of Compliance Manager. 2) Obtain the complete population of occurrences for the period and verify completeness (system-generated list). 3) Select a sample per the Sampling Guide. 4) Inspect evidence (Dated system description) for performance, timeliness, reviewer independence and follow-up of exceptions. | N9: Annual | O9: =IFERROR(INDEX('Sampling Guide'!$B$2:$B$20,MATCH(N9,'Sampling Guide'!$A$2:$A$20,0)),"TBD") -> 1 | Q9: In-scope repo list = GitHub custom property soc2_scope=true
A10: HR-01 | B10: Human Resources | C10: Background checks | D10: Background checks are completed for new hires prior to granting access to production or customer data, where legally permitted. | E10: HRIS | F10: Preventive | G10: IT-dependent manual | H10: Per event | I10: Head of People | J10: CC1.4 | K10: Background check completion records for sampled hires | L10: HRIS report of hires with check status | M10: 1) Inquire of Head of People. 2) Obtain the complete population of occurrences for the period and verify completeness (system-generated list). 3) Select a sample per the Sampling Guide. 4) Inspect evidence (Background check completion records for sampled hires) for performance, timeliness, reviewer independence and follow-up of exceptions. | N10: Per event / multiple times per day | O10: =IFERROR(INDEX('Sampling Guide'!$B$2:$B$20,MATCH(N10,'Sampling Guide'!$A$2:$A$20,0)),"TBD") -> 25
A11: HR-02 | B11: Human Resources | C11: Code of conduct and policy acknowledgment | D11: Personnel acknowledge the code of conduct, acceptable use and security policies at hire and annually. | E11: HRIS, GRC | F11: Preventive | G11: IT-dependent manual | H11: Per event / Annual | I11: Head of People | J11: CC1.1, CC1.5, CC2.2 | K11: Signed acknowledgments for sampled personnel | L11: HRIS/LMS acknowledgment export | M11: 1) Inquire of Head of People. 2) Obtain the complete population of occurrences for the period and verify completeness (system-generated list). 3) Select a sample per the Sampling Guide. 4) Inspect evidence (Signed acknowledgments for sampled personnel) for performance, timeliness, reviewer independence and follow-up of exceptions. | N11: Per event / multiple times per day | O11: =IFERROR(INDEX('Sampling Guide'!$B$2:$B$20,MATCH(N11,'Sampling Guide'!$A$2:$A$20,0)),"TBD") -> 25
A12: HR-03 | B12: Human Resources | C12: Security awareness training | D12: Personnel complete security awareness training within 30 days of hire and annually; engineers complete secure-coding training annually. | E12: HRIS, GRC | F12: Preventive | G12: IT-dependent manual | H12: Per event / Annual | I12: CISO / Security Lead | J12: CC1.4, CC2.2 | K12: Training completion report; training content | L12: LMS completion export on schedule | M12: 1) Inquire of CISO / Security Lead. 2) Obtain the complete population of occurrences for the period and verify completeness (system-generated list). 3) Select a sample per the Sampling Guide. 4) Inspect evidence (Training completion report) for performance, timeliness, reviewer independence and follow-up of exceptions. | N12: Per event / multiple times per day | O12: =IFERROR(INDEX('Sampling Guide'!$B$2:$B$20,MATCH(N12,'Sampling Guide'!$A$2:$A$20,0)),"TBD") -> 25
A13: HR-04 | B13: Human Resources | C13: Job descriptions and performance reviews | D13: Roles have documented job descriptions including security responsibilities; performance evaluations occur at least annually. | E13: HRIS | F13: Preventive | G13: Manual | H13: Annual | I13: Head of People | J13: CC1.3, CC1.4, CC1.5 | K13: Job descriptions; completed performance review evidence (sampled) | L13: HRIS report | M13: 1) Inquire of Head of People. 2) Obtain the complete population of occurrences for the period and verify completeness (system-generated list). 3) Select a sample per the Sampling Guide. 4) Inspect evidence (Job descriptions) for performance, timeliness, reviewer independence and follow-up of exceptions. | N13: Annual | O13: =IFERROR(INDEX('Sampling Guide'!$B$2:$B$20,MATCH(N13,'Sampling Guide'!$A$2:$A$20,0)),"TBD") -> 1
A14: HR-05 | B14: Human Resources | C14: Disciplinary process | D14: A documented sanctions process applies to personnel who violate security policies. | E14: HRIS | F14: Corrective | G14: Manual | H14: Per event | I14: Head of People | J14: CC1.5 | K14: Handbook sanctions section; case log if any | L14: n/a | M14: 1) Inquire of Head of People. 2) Obtain the complete population of occurrences for the period and verify completeness (system-generated list). 3) Select a sample per the Sampling Guide. 4) Inspect evidence (Handbook sanctions section) for performance, timeliness, reviewer independence and follow-up of exceptions. | N14: Per event / multiple times per day | O14: =IFERROR(INDEX('Sampling Guide'!$B$2:$B$20,MATCH(N14,'Sampling Guide'!$A$2:$A$20,0)),"TBD") -> 25
A15: RSK-01 | B15: Risk Management | C15: Annual risk assessment | D15: A formal risk assessment, including fraud risk and technology/threat changes, is performed at least annually; risks are scored and assigned owners and treatment plans. | E15: GRC | F15: Detective | G15: Manual | H15: Annual | I15: CISO / Security Lead | J15: CC3.1, CC3.2, CC3.3, CC3.4, CC5.1 | K15: Risk assessment report; risk register with scores and treatment | L15: Risk register maintained in GRC tool / workbook | M15: 1) Inquire of CISO / Security Lead. 2) Obtain the complete population of occurrences for the period and verify completeness (system-generated list). 3) Select a sample per the Sampling Guide. 4) Inspect evidence (Risk assessment report) for performance, timeliness, reviewer independence and follow-up of exceptions. | N15: Annual | O15: =IFERROR(INDEX('Sampling Guide'!$B$2:$B$20,MATCH(N15,'Sampling Guide'!$A$2:$A$20,0)),"TBD") -> 1
A16: RSK-02 | B16: Risk Management | C16: Security objectives defined | D16: Security objectives aligned with service commitments and system requirements are documented and reviewed annually. | E16: GRC | F16: Preventive | G16: Manual | H16: Annual | I16: CISO / Security Lead | J16: CC3.1 | K16: Documented objectives with approval | L16: n/a | M16: 1) Inquire of CISO / Security Lead. 2) Obtain the complete population of occurrences for the period and verify completeness (system-generated list). 3) Select a sample per the Sampling Guide. 4) Inspect evidence (Documented objectives with approval) for performance, timeliness, reviewer independence and follow-up of exceptions. | N16: Annual | O16: =IFERROR(INDEX('Sampling Guide'!$B$2:$B$20,MATCH(N16,'Sampling Guide'!$A$2:$A$20,0)),"TBD") -> 1
A17: RSK-03 | B17: Risk Management | C17: Change-driven risk review | D17: Significant changes (new subsystem, vendor, region, acquisition, architecture change) trigger a risk review before go-live. | E17: ITSM, GRC | F17: Preventive | G17: Manual | H17: Per event | I17: CISO / Security Lead | J17: CC3.4, CC9.1 | K17: Architecture/security review tickets for significant changes | L17: Ticket type 'security-review' required by intake workflow | M17: 1) Inquire of CISO / Security Lead. 2) Obtain the complete population of occurrences for the period and verify completeness (system-generated list). 3) Select a sample per the Sampling Guide. 4) Inspect evidence (Architecture/security review tickets for significant changes) for performance, timeliness, reviewer independence and follow-up of exceptions. | N17: Per event / multiple times per day | O17: =IFERROR(INDEX('Sampling Guide'!$B$2:$B$20,MATCH(N17,'Sampling Guide'!$A$2:$A$20,0)),"TBD") -> 25 | Q17: ServiceNow catalog item 'Security design review' for significant changes
A18: RSK-04 | B18: Risk Management | C18: Cyber insurance | D18: Cyber liability insurance is maintained and reviewed annually for adequacy. | E18: GRC | F18: Corrective | G18: Manual | H18: Annual | I18: CFO | J18: CC9.1 | K18: Insurance certificate / policy summary | L18: n/a | M18: 1) Inquire of CFO. 2) Obtain the complete population of occurrences for the period and verify completeness (system-generated list). 3) Select a sample per the Sampling Guide. 4) Inspect evidence (Insurance certificate / policy summary) for performance, timeliness, reviewer independence and follow-up of exceptions. | N18: Annual | O18: =IFERROR(INDEX('Sampling Guide'!$B$2:$B$20,MATCH(N18,'Sampling Guide'!$A$2:$A$20,0)),"TBD") -> 1
A19: VEN-01 | B19: Vendor Management | C19: Vendor inventory and risk tiering | D19: All vendors and sub-service organizations processing company or customer data are inventoried and risk-tiered. | E19: GRC | F19: Preventive | G19: Manual | H19: Ongoing / Annual review | I19: Compliance Manager | J19: CC9.2 | K19: Vendor inventory with tier and data classification | L19: Inventory seeded from SSO app catalog and AP spend report | M19: 1) Inquire of Compliance Manager. 2) Obtain the complete population of occurrences for the period and verify completeness (system-generated list). 3) Select a sample per the Sampling Guide. 4) Inspect evidence (Vendor inventory with tier and data classification) for performance, timeliness, reviewer independence and follow-up of exceptions. | N19: Per event / multiple times per day | O19: =IFERROR(INDEX('Sampling Guide'!$B$2:$B$20,MATCH(N19,'Sampling Guide'!$A$2:$A$20,0)),"TBD") -> 25
A20: VEN-02 | B20: Vendor Management | C20: Vendor security due diligence | D20: Before onboarding and annually for critical vendors, security posture is reviewed (SOC 2 report, questionnaire), including complementary user entity controls (CUECs). | E20: GRC | F20: Detective | G20: Manual | H20: Per event / Annual | I20: Compliance Manager | J20: CC9.2, CC2.3 | K20: Vendor SOC reports and review memos incl. CUEC mapping | L20: Reminder tickets auto-generated 30 days before review due | M20: 1) Inquire of Compliance Manager. 2) Obtain the complete population of occurrences for the period and verify completeness (system-generated list). 3) Select a sample per the Sampling Guide. 4) Inspect evidence (Vendor SOC reports and review memos incl. CUEC mapping) for performance, timeliness, reviewer independence and follow-up of exceptions. | N20: Per event / multiple times per day | O20: =IFERROR(INDEX('Sampling Guide'!$B$2:$B$20,MATCH(N20,'Sampling Guide'!$A$2:$A$20,0)),"TBD") -> 25 | Q20: ServiceNow task / VRM (if licensed) generated 30 days before review
A21: VEN-03 | B21: Vendor Management | C21: Vendor contracts include security terms | D21: Contracts with critical vendors include confidentiality, security, breach notification and right-to-audit terms. | E21: GRC | F21: Preventive | G21: Manual | H21: Per event | I21: Legal / Compliance | J21: CC9.2 | K21: Executed contracts/DPAs for sampled vendors | L21: n/a | M21: 1) Inquire of Legal / Compliance. 2) Obtain the complete population of occurrences for the period and verify completeness (system-generated list). 3) Select a sample per the Sampling Guide. 4) Inspect evidence (Executed contracts/DPAs for sampled vendors) for performance, timeliness, reviewer independence and follow-up of exceptions. | N21: Per event / multiple times per day | O21: =IFERROR(INDEX('Sampling Guide'!$B$2:$B$20,MATCH(N21,'Sampling Guide'!$A$2:$A$20,0)),"TBD") -> 25
A22: IAM-01 | B22: Identity & Access | C22: Centralized SSO with MFA | D22: Access to in-scope subsystems (SCM, CI/CD, cloud console/API, SIEM, ITSM, registry) is federated through the IdP with phishing-resistant MFA enforced; local accounts are disabled or break-glass only. | E22: IDP, SCM, CI, CLD, SIEM, ITSM, REG | F22: Preventive | G22: Automated | H22: Continuous | I22: IT / Identity Admin | J22: CC6.1, CC6.2 | K22: IdP authentication policy config; per-app SSO enforcement settings; list of local accounts | L22: Nightly collector exports IdP policies and app SSO settings via API | M22: 1) Inquire of IT / Identity Admin to understand the control. 2) Inspect the configuration in IDP, SCM, CI, CLD, SIEM, ITSM, REG at a point in time. 3) Inspect change/drift history to confirm the configuration was in effect throughout the period. 4) Where feasible, re-perform (attempt a prohibited action) and observe it is blocked or alerted. 5) Rely on ITGCs (CHG-01, IAM-04) over the configuration. | N22: Automated (continuous) | O22: =IFERROR(INDEX('Sampling Guide'!$B$2:$B$20,MATCH(N22,'Sampling Guide'!$A$2:$A$20,0)),"TBD") -> 1 | Q22: GitHub EMU / enterprise SAML SSO via [IdP]; ServiceNow SAML SSO via [IdP]; local logins disabled (break-glass only)
A23: IAM-02 | B23: Identity & Access | C23: HRIS-driven provisioning (joiner) | D23: New user identities are created in the IdP from the HRIS joiner event; application access is granted via role-based groups following an approved access request. | E23: HRIS, IDP, ITSM | F23: Preventive | G23: Automated | H23: Per event | I23: IT / Identity Admin | J23: CC6.2, CC6.3 | K23: Joiner events; access request tickets with approval for sampled hires | L23: SCIM/HRIS webhook logs; ITSM approval records | M23: 1) Inquire of IT / Identity Admin to understand the control. 2) Inspect the configuration in HRIS, IDP, ITSM at a point in time. 3) Inspect change/drift history to confirm the configuration was in effect throughout the period. 4) Where feasible, re-perform (attempt a prohibited action) and observe it is blocked or alerted. 5) Rely on ITGCs (CHG-01, IAM-04) over the configuration. | N23: Per event / multiple times per day | O23: =IFERROR(INDEX('Sampling Guide'!$B$2:$B$20,MATCH(N23,'Sampling Guide'!$A$2:$A$20,0)),"TBD") -> 25 | Q23: ServiceNow catalog item 'Access to in-scope system' (manager + system-owner approval) → IdP group → SCIM to GitHub / ServiceNow
A24: IAM-03 | B24: Identity & Access | C24: Timely deprovisioning (leaver) | D24: Terminated users are disabled in the IdP within 24 hours of termination (immediately for involuntary); downstream app access and tokens are revoked via SCIM. | E24: HRIS, IDP, SCM, CLD | F24: Preventive | G24: Automated | H24: Per event | I24: IT / Identity Admin | J24: CC6.2, CC6.3 | K24: HRIS termination list vs. IdP deactivation timestamps | L24: Daily reconciliation job flags leavers active >24h and opens ticket | M24: 1) Inquire of IT / Identity Admin to understand the control. 2) Inspect the configuration in HRIS, IDP, SCM, CLD at a point in time. 3) Inspect change/drift history to confirm the configuration was in effect throughout the period. 4) Where feasible, re-perform (attempt a prohibited action) and observe it is blocked or alerted. 5) Rely on ITGCs (CHG-01, IAM-04) over the configuration. | N24: Per event / multiple times per day | O24: =IFERROR(INDEX('Sampling Guide'!$B$2:$B$20,MATCH(N24,'Sampling Guide'!$A$2:$A$20,0)),"TBD") -> 25 | Q24: IdP deactivation → SCIM suspends GitHub (EMU) user; ServiceNow user active=false; leaver recon ticket in ServiceNow
A25: IAM-04 | B25: Identity & Access | C25: Quarterly user access reviews | D25: System owners review user and privileged access to in-scope subsystems quarterly; inappropriate access is removed and tracked to closure. | E25: IDP, SCM, CLD, CI, SIEM, ITSM | F25: Detective | G25: IT-dependent manual | H25: Quarterly | I25: System Owners | J25: CC6.2, CC6.3, CC4.1 | K25: Access review workbooks with reviewer sign-off; removal tickets | L25: Collector generates user lists per system; completeness via API row counts | M25: 1) Inquire of System Owners. 2) Obtain the complete population of occurrences for the period and verify completeness (system-generated list). 3) Select a sample per the Sampling Guide. 4) Inspect evidence (Access review workbooks with reviewer sign-off) for performance, timeliness, reviewer independence and follow-up of exceptions. | N25: Quarterly | O25: =IFERROR(INDEX('Sampling Guide'!$B$2:$B$20,MATCH(N25,'Sampling Guide'!$A$2:$A$20,0)),"TBD") -> 2 | Q25: Quarterly: GitHub org owners/members/teams/outside collaborators; ServiceNow sys_user_has_role (admin, security_admin, change_manager, CAB)
A26: IAM-05 | B26: Identity & Access | C26: Least privilege and role-based access | D26: Access is granted through predefined roles/groups; production write access is restricted to on-call/SRE roles; standing admin access is minimized. | E26: IDP, CLD, K8S | F26: Preventive | G26: Automated | H26: Continuous | I26: Engineering Manager | J26: CC6.1, CC6.3 | K26: Role definitions; IAM policy exports; group membership | L26: IaC-managed IAM; policy-as-code checks in CI | M26: 1) Inquire of Engineering Manager to understand the control. 2) Inspect the configuration in IDP, CLD, K8S at a point in time. 3) Inspect change/drift history to confirm the configuration was in effect throughout the period. 4) Where feasible, re-perform (attempt a prohibited action) and observe it is blocked or alerted. 5) Rely on ITGCs (CHG-01, IAM-04) over the configuration. | N26: Automated (continuous) | O26: =IFERROR(INDEX('Sampling Guide'!$B$2:$B$20,MATCH(N26,'Sampling Guide'!$A$2:$A$20,0)),"TBD") -> 1 | Q26: GitHub base permission = none; repo admin via teams; ServiceNow roles only via groups
A27: IAM-06 | B27: Identity & Access | C27: Just-in-time privileged access | D27: Privileged production access is time-bound, requested with justification, approved, and logged. | E27: IDP, CLD, ITSM, SIEM | F27: Preventive | G27: Automated | H27: Per event | I27: Engineering Manager | J27: CC6.1, CC6.3, CC7.2 | K27: JIT elevation logs with approvals and expiry | L27: Elevation events forwarded to SIEM | M27: 1) Inquire of Engineering Manager to understand the control. 2) Inspect the configuration in IDP, CLD, ITSM, SIEM at a point in time. 3) Inspect change/drift history to confirm the configuration was in effect throughout the period. 4) Where feasible, re-perform (attempt a prohibited action) and observe it is blocked or alerted. 5) Rely on ITGCs (CHG-01, IAM-04) over the configuration. | N27: Per event / multiple times per day | O27: =IFERROR(INDEX('Sampling Guide'!$B$2:$B$20,MATCH(N27,'Sampling Guide'!$A$2:$A$20,0)),"TBD") -> 25
A28: IAM-07 | B28: Identity & Access | C28: Service accounts and machine identities | D28: Non-human identities use workload identity federation (e.g., OIDC) or short-lived credentials; static keys are prohibited or rotated <=90 days and inventoried. | E28: CI, CLD, VAULT | F28: Preventive | G28: Automated | H28: Continuous | I28: Platform Engineering | J28: CC6.1, CC6.2 | K28: Service account inventory; key age report; OIDC trust config | L28: Weekly key-age scan; findings auto-ticketed | M28: 1) Inquire of Platform Engineering to understand the control. 2) Inspect the configuration in CI, CLD, VAULT at a point in time. 3) Inspect change/drift history to confirm the configuration was in effect throughout the period. 4) Where feasible, re-perform (attempt a prohibited action) and observe it is blocked or alerted. 5) Rely on ITGCs (CHG-01, IAM-04) over the configuration. | N28: Automated (continuous) | O28: =IFERROR(INDEX('Sampling Guide'!$B$2:$B$20,MATCH(N28,'Sampling Guide'!$A$2:$A$20,0)),"TBD") -> 1 | Q28: GitHub: classic PATs blocked, fine-grained PATs approved ≤90d, GitHub Apps approved; OIDC for cloud; ServiceNow integration users web-service-only
A29: IAM-08 | B29: Identity & Access | C29: Password and authentication standards | D29: Authentication settings (length, lockout, session timeout) conform to the Access Control Policy. | E29: IDP | F29: Preventive | G29: Automated | H29: Continuous | I29: IT / Identity Admin | J29: CC6.1 | K29: IdP policy configuration export | L29: Nightly config export with drift diff | M29: 1) Inquire of IT / Identity Admin to understand the control. 2) Inspect the configuration in IDP at a point in time. 3) Inspect change/drift history to confirm the configuration was in effect throughout the period. 4) Where feasible, re-perform (attempt a prohibited action) and observe it is blocked or alerted. 5) Rely on ITGCs (CHG-01, IAM-04) over the configuration. | N29: Automated (continuous) | O29: =IFERROR(INDEX('Sampling Guide'!$B$2:$B$20,MATCH(N29,'Sampling Guide'!$A$2:$A$20,0)),"TBD") -> 1
A30: IAM-09 | B30: Identity & Access | C30: Break-glass accounts | D30: Emergency accounts are vaulted, MFA-protected, alert on use, and use is reviewed. | E30: VAULT, CLD, SIEM | F30: Detective | G30: Automated | H30: Per event | I30: CISO / Security Lead | J30: CC6.1, CC7.2 | K30: Break-glass inventory; alert rule; usage review tickets | L30: SIEM rule fires on any break-glass login | M30: 1) Inquire of CISO / Security Lead to understand the control. 2) Inspect the configuration in VAULT, CLD, SIEM at a point in time. 3) Inspect change/drift history to confirm the configuration was in effect throughout the period. 4) Where feasible, re-perform (attempt a prohibited action) and observe it is blocked or alerted. 5) Rely on ITGCs (CHG-01, IAM-04) over the configuration. | N30: Per event / multiple times per day | O30: =IFERROR(INDEX('Sampling Guide'!$B$2:$B$20,MATCH(N30,'Sampling Guide'!$A$2:$A$20,0)),"TBD") -> 25 | Q30: ServiceNow local admin + GitHub enterprise owner break-glass vaulted; SIEM alert on use
A31: CHG-01 | B31: Change Management | C31: Branch protection on default branches | D31: Default/release branches require pull requests, at least one approval from a code owner other than the author, passing status checks, and prohibit force-push and deletion; admins cannot bypass. | E31: SCM | F31: Preventive | G31: Automated | H31: Continuous | I31: Engineering Manager | J31: CC8.1, CC5.2 | K31: Branch protection/ruleset configuration export for in-scope repos | L31: Nightly collector exports rulesets; drift alerts to Security | M31: 1) Inquire of Engineering Manager to understand the control. 2) Inspect the configuration in SCM at a point in time. 3) Inspect change/drift history to confirm the configuration was in effect throughout the period. 4) Where feasible, re-perform (attempt a prohibited action) and observe it is blocked or alerted. 5) Rely on ITGCs (CHG-01, IAM-04) over the configuration. | N31: Automated (continuous) | O31: =IFERROR(INDEX('Sampling Guide'!$B$2:$B$20,MATCH(N31,'Sampling Guide'!$A$2:$A$20,0)),"TBD") -> 1 | Q31: GitHub org ruleset 'soc2-default-branch-protection' on repos with custom property soc2_scope=true; bypass list empty; tag ruleset for releases
A32: CHG-02 | B32: Change Management | C32: Peer review of code changes | D32: All changes merged to production branches are peer reviewed and approved by someone other than the author. | E32: SCM | F32: Preventive | G32: Automated | H32: Per event | I32: Engineering Manager | J32: CC8.1 | K32: Population of merged PRs with reviewer != author for sampled changes | L32: Collector pulls merged PR list + reviews via SCM API | M32: 1) Inquire of Engineering Manager to understand the control. 2) Inspect the configuration in SCM at a point in time. 3) Inspect change/drift history to confirm the configuration was in effect throughout the period. 4) Where feasible, re-perform (attempt a prohibited action) and observe it is blocked or alerted. 5) Rely on ITGCs (CHG-01, IAM-04) over the configuration. | N32: Per event / multiple times per day | O32: =IFERROR(INDEX('Sampling Guide'!$B$2:$B$20,MATCH(N32,'Sampling Guide'!$A$2:$A$20,0)),"TBD") -> 25 | Q32: Ruleset: code-owner review, require_last_push_approval, dismiss stale reviews; Actions not allowed to approve PRs
A33: CHG-03 | B33: Change Management | C33: Automated testing in CI | D33: CI runs unit/integration tests on every PR; failing tests block merge. | E33: CI, SCM | F33: Preventive | G33: Automated | H33: Per event | I33: Engineering Manager | J33: CC8.1 | K33: Required status checks config; CI run logs for sampled PRs | L33: CI run metadata archived to evidence store | M33: 1) Inquire of Engineering Manager to understand the control. 2) Inspect the configuration in CI, SCM at a point in time. 3) Inspect change/drift history to confirm the configuration was in effect throughout the period. 4) Where feasible, re-perform (attempt a prohibited action) and observe it is blocked or alerted. 5) Rely on ITGCs (CHG-01, IAM-04) over the configuration. | N33: Per event / multiple times per day | O33: =IFERROR(INDEX('Sampling Guide'!$B$2:$B$20,MATCH(N33,'Sampling Guide'!$A$2:$A$20,0)),"TBD") -> 25 | Q33: Required status check 'ci / test' in GitHub Actions
A34: CHG-04 | B34: Change Management | C34: Security scanning in pipeline | D34: SAST, dependency (SCA), secret scanning and container image scanning run in CI; critical/high findings block release unless an approved exception exists. | E34: CI, SEC, REG | F34: Preventive | G34: Automated | H34: Per event | I34: AppSec Lead | J34: CC8.1, CC7.1, CC6.8 | K34: Scanner config; pipeline gate policy; findings and exception tickets | L34: Scanner results exported to SIEM/GRC | M34: 1) Inquire of AppSec Lead to understand the control. 2) Inspect the configuration in CI, SEC, REG at a point in time. 3) Inspect change/drift history to confirm the configuration was in effect throughout the period. 4) Where feasible, re-perform (attempt a prohibited action) and observe it is blocked or alerted. 5) Rely on ITGCs (CHG-01, IAM-04) over the configuration. | N34: Per event / multiple times per day | O34: =IFERROR(INDEX('Sampling Guide'!$B$2:$B$20,MATCH(N34,'Sampling Guide'!$A$2:$A$20,0)),"TBD") -> 25 | Q34: CodeQL (ruleset code_scanning rule, High+ blocks), dependency-review action, secret scanning push protection with delegated bypass
A35: CHG-05 | B35: Change Management | C35: Pipeline-only production deployment | D35: Production deployments occur only through the CI/CD pipeline using a deploy identity; humans have no standing direct write/deploy access to production. | E35: CI, CLD, K8S | F35: Preventive | G35: Automated | H35: Continuous | I35: Platform Engineering | J35: CC8.1, CC6.1, CC5.2 | K35: Deploy role trust policy; IAM exports; cloud audit logs showing deploys by pipeline identity | L35: Monthly query of cloud audit logs for non-pipeline prod changes | M35: 1) Inquire of Platform Engineering to understand the control. 2) Inspect the configuration in CI, CLD, K8S at a point in time. 3) Inspect change/drift history to confirm the configuration was in effect throughout the period. 4) Where feasible, re-perform (attempt a prohibited action) and observe it is blocked or alerted. 5) Rely on ITGCs (CHG-01, IAM-04) over the configuration. | N35: Automated (continuous) | O35: =IFERROR(INDEX('Sampling Guide'!$B$2:$B$20,MATCH(N35,'Sampling Guide'!$A$2:$A$20,0)),"TBD") -> 1 | Q35: Cloud role trusts GitHub OIDC sub '...:environment:production' only; production environment with ServiceNow deployment gate; admin bypass disabled
A36: CHG-06 | B36: Change Management | C36: Deployment traceability | D36: Every production deployment is traceable to a commit SHA, approved PR, pipeline run and (where required) change ticket. | E36: CI, SCM, ITSM, REG | F36: Detective | G36: Automated | H36: Per event | I36: Engineering Manager | J36: CC8.1, CC2.1 | K36: Deployment log linking SHA -> PR -> pipeline run -> artifact digest | L36: Pipeline emits deployment record to evidence store | M36: 1) Inquire of Engineering Manager to understand the control. 2) Inspect the configuration in CI, SCM, ITSM, REG at a point in time. 3) Inspect change/drift history to confirm the configuration was in effect throughout the period. 4) Where feasible, re-perform (attempt a prohibited action) and observe it is blocked or alerted. 5) Rely on ITGCs (CHG-01, IAM-04) over the configuration. | N36: Per event / multiple times per day | O36: =IFERROR(INDEX('Sampling Guide'!$B$2:$B$20,MATCH(N36,'Sampling Guide'!$A$2:$A$20,0)),"TBD") -> 25 | Q36: ServiceNow DevOps Change Velocity change per production deployment; quarterly GitHub deployments ↔ ServiceNow change reconciliation
A37: CHG-07 | B37: Change Management | C37: Signed, provenance-attested artifacts | D37: Build artifacts are produced by the CI system, signed, and carry build provenance; admission policy rejects unsigned images in production. | E37: CI, REG, K8S | F37: Preventive | G37: Automated | H37: Continuous | I37: Platform Engineering | J37: CC8.1, CC6.8 | K37: Signing config; admission policy; sample verification output | L37: Admission controller logs to SIEM | M37: 1) Inquire of Platform Engineering to understand the control. 2) Inspect the configuration in CI, REG, K8S at a point in time. 3) Inspect change/drift history to confirm the configuration was in effect throughout the period. 4) Where feasible, re-perform (attempt a prohibited action) and observe it is blocked or alerted. 5) Rely on ITGCs (CHG-01, IAM-04) over the configuration. | N37: Automated (continuous) | O37: =IFERROR(INDEX('Sampling Guide'!$B$2:$B$20,MATCH(N37,'Sampling Guide'!$A$2:$A$20,0)),"TBD") -> 1 | Q37: actions/attest-build-provenance; 'gh attestation verify' before deploy; cluster admission policy
A38: CHG-08 | B38: Change Management | C38: Environment segregation | D38: Development, staging and production are logically separated (separate accounts/projects/clusters); production data is not used in non-production without approval and masking. | E38: CLD, K8S, IAC | F38: Preventive | G38: Automated | H38: Continuous | I38: Platform Engineering | J38: CC8.1, CC6.1 | K38: Account/project structure diagram; network config; IAM boundaries | L38: IaC state export | M38: 1) Inquire of Platform Engineering to understand the control. 2) Inspect the configuration in CLD, K8S, IAC at a point in time. 3) Inspect change/drift history to confirm the configuration was in effect throughout the period. 4) Where feasible, re-perform (attempt a prohibited action) and observe it is blocked or alerted. 5) Rely on ITGCs (CHG-01, IAM-04) over the configuration. | N38: Automated (continuous) | O38: =IFERROR(INDEX('Sampling Guide'!$B$2:$B$20,MATCH(N38,'Sampling Guide'!$A$2:$A$20,0)),"TBD") -> 1
A39: CHG-09 | B39: Change Management | C39: Emergency change procedure | D39: Emergency changes follow an expedited path and receive retrospective review and approval within 2 business days. | E39: ITSM, SCM | F39: Corrective | G39: IT-dependent manual | H39: Per event | I39: Engineering Manager | J39: CC8.1 | K39: Emergency change tickets with retrospective approval | L39: Ticket type 'emergency-change' with SLA timer | M39: 1) Inquire of Engineering Manager. 2) Obtain the complete population of occurrences for the period and verify completeness (system-generated list). 3) Select a sample per the Sampling Guide. 4) Inspect evidence (Emergency change tickets with retrospective approval) for performance, timeliness, reviewer independence and follow-up of exceptions. | N39: Per event / multiple times per day | O39: =IFERROR(INDEX('Sampling Guide'!$B$2:$B$20,MATCH(N39,'Sampling Guide'!$A$2:$A$20,0)),"TBD") -> 25 | Q39: ServiceNow Emergency change model; retrospective approval task ≤2 BD; ruleset bypass only via settings-as-code break-glass
A40: CHG-10 | B40: Change Management | C40: Infrastructure changes via IaC | D40: Infrastructure changes are defined in IaC, peer reviewed, planned in CI (plan output attached), and applied by the pipeline. | E40: IAC, SCM, CI, CLD | F40: Preventive | G40: Automated | H40: Per event | I40: Platform Engineering | J40: CC8.1, CC7.1 | K40: IaC PRs with plan output and approval; apply logs | L40: Pipeline archives plan/apply logs | M40: 1) Inquire of Platform Engineering to understand the control. 2) Inspect the configuration in IAC, SCM, CI, CLD at a point in time. 3) Inspect change/drift history to confirm the configuration was in effect throughout the period. 4) Where feasible, re-perform (attempt a prohibited action) and observe it is blocked or alerted. 5) Rely on ITGCs (CHG-01, IAM-04) over the configuration. | N40: Per event / multiple times per day | O40: =IFERROR(INDEX('Sampling Guide'!$B$2:$B$20,MATCH(N40,'Sampling Guide'!$A$2:$A$20,0)),"TBD") -> 25 | Q40: IaC PRs in GitHub; plan posted by Actions; apply by Actions via OIDC
...

Sheet TSC Coverage
A1: Criterion | B1: Category | C1: Summary (paraphrased) | D1: # Mapped Controls | E1: # Implemented | F1: Design Coverage | G1: Readiness
A2: CC1.1 | B2: Control Environment | C2: Demonstrates commitment to integrity and ethical values | D2: =COUNTIF('Control Matrix'!$J$2:$J$70,"*"&A2&"*") -> 3 | E2: =COUNTIFS('Control Matrix'!$J$2:$J$70,"*"&A2&"*",'Control Matrix'!$R$2:$R$70,"Implemented") -> 1 | F2: =IF(D2>0,"Covered","GAP") -> Covered | G2: =IF(D2=0,"GAP",IF(E2=D2,"Ready",IF(E2>0,"In progress","Not started"))) -> In progress
A3: CC1.2 | B3: Control Environment | C3: Board exercises oversight responsibility, independent of management | D3: =COUNTIF('Control Matrix'!$J$2:$J$70,"*"&A3&"*") -> 1 | E3: =COUNTIFS('Control Matrix'!$J$2:$J$70,"*"&A3&"*",'Control Matrix'!$R$2:$R$70,"Implemented") -> 0 | F3: =IF(D3>0,"Covered","GAP") -> Covered | G3: =IF(D3=0,"GAP",IF(E3=D3,"Ready",IF(E3>0,"In progress","Not started"))) -> Not started
A4: CC1.3 | B4: Control Environment | C4: Management establishes structures, reporting lines, authorities and responsibilities | D4: =COUNTIF('Control Matrix'!$J$2:$J$70,"*"&A4&"*") -> 3 | E4: =COUNTIFS('Control Matrix'!$J$2:$J$70,"*"&A4&"*",'Control Matrix'!$R$2:$R$70,"Implemented") -> 0 | F4: =IF(D4>0,"Covered","GAP") -> Covered | G4: =IF(D4=0,"GAP",IF(E4=D4,"Ready",IF(E4>0,"In progress","Not started"))) -> Not started
A5: CC1.4 | B5: Control Environment | C5: Demonstrates commitment to attract, develop and retain competent individuals | D5: =COUNTIF('Control Matrix'!$J$2:$J$70,"*"&A5&"*") -> 3 | E5: =COUNTIFS('Control Matrix'!$J$2:$J$70,"*"&A5&"*",'Control Matrix'!$R$2:$R$70,"Implemented") -> 0 | F5: =IF(D5>0,"Covered","GAP") -> Covered | G5: =IF(D5=0,"GAP",IF(E5=D5,"Ready",IF(E5>0,"In progress","Not started"))) -> Not started
A6: CC1.5 | B6: Control Environment | C6: Holds individuals accountable for internal control responsibilities | D6: =COUNTIF('Control Matrix'!$J$2:$J$70,"*"&A6&"*") -> 3 | E6: =COUNTIFS('Control Matrix'!$J$2:$J$70,"*"&A6&"*",'Control Matrix'!$R$2:$R$70,"Implemented") -> 0 | F6: =IF(D6>0,"Covered","GAP") -> Covered | G6: =IF(D6=0,"GAP",IF(E6=D6,"Ready",IF(E6>0,"In progress","Not started"))) -> Not started
A7: CC2.1 | B7: Communication & Information | C7: Obtains/generates and uses relevant, quality information | D7: =COUNTIF('Control Matrix'!$J$2:$J$70,"*"&A7&"*") -> 5 | E7: =COUNTIFS('Control Matrix'!$J$2:$J$70,"*"&A7&"*",'Control Matrix'!$R$2:$R$70,"Implemented") -> 0 | F7: =IF(D7>0,"Covered","GAP") -> Covered | G7: =IF(D7=0,"GAP",IF(E7=D7,"Ready",IF(E7>0,"In progress","Not started"))) -> Not started
A8: CC2.2 | B8: Communication & Information | C8: Internally communicates objectives and responsibilities for internal control | D8: =COUNTIF('Control Matrix'!$J$2:$J$70,"*"&A8&"*") -> 4 | E8: =COUNTIFS('Control Matrix'!$J$2:$J$70,"*"&A8&"*",'Control Matrix'!$R$2:$R$70,"Implemented") -> 1 | F8: =IF(D8>0,"Covered","GAP") -> Covered | G8: =IF(D8=0,"GAP",IF(E8=D8,"Ready",IF(E8>0,"In progress","Not started"))) -> In progress
A9: CC2.3 | B9: Communication & Information | C9: Communicates with external parties regarding internal control matters | D9: =COUNTIF('Control Matrix'!$J$2:$J$70,"*"&A9&"*") -> 5 | E9: =COUNTIFS('Control Matrix'!$J$2:$J$70,"*"&A9&"*",'Control Matrix'!$R$2:$R$70,"Implemented") -> 0 | F9: =IF(D9>0,"Covered","GAP") -> Covered | G9: =IF(D9=0,"GAP",IF(E9=D9,"Ready",IF(E9>0,"In progress","Not started"))) -> Not started
A10: CC3.1 | B10: Risk Assessment | C10: Specifies objectives with sufficient clarity to identify and assess risks | D10: =COUNTIF('Control Matrix'!$J$2:$J$70,"*"&A10&"*") -> 2 | E10: =COUNTIFS('Control Matrix'!$J$2:$J$70,"*"&A10&"*",'Control Matrix'!$R$2:$R$70,"Implemented") -> 0 | F10: =IF(D10>0,"Covered","GAP") -> Covered | G10: =IF(D10=0,"GAP",IF(E10=D10,"Ready",IF(E10>0,"In progress","Not started"))) -> Not started
A11: CC3.2 | B11: Risk Assessment | C11: Identifies and analyzes risks to the achievement of objectives | D11: =COUNTIF('Control Matrix'!$J$2:$J$70,"*"&A11&"*") -> 2 | E11: =COUNTIFS('Control Matrix'!$J$2:$J$70,"*"&A11&"*",'Control Matrix'!$R$2:$R$70,"Implemented") -> 0 | F11: =IF(D11>0,"Covered","GAP") -> Covered | G11: =IF(D11=0,"GAP",IF(E11=D11,"Ready",IF(E11>0,"In progress","Not started"))) -> Not started
A12: CC3.3 | B12: Risk Assessment | C12: Considers the potential for fraud in assessing risks | D12: =COUNTIF('Control Matrix'!$J$2:$J$70,"*"&A12&"*") -> 1 | E12: =COUNTIFS('Control Matrix'!$J$2:$J$70,"*"&A12&"*",'Control Matrix'!$R$2:$R$70,"Implemented") -> 0 | F12: =IF(D12>0,"Covered","GAP") -> Covered | G12: =IF(D12=0,"GAP",IF(E12=D12,"Ready",IF(E12>0,"In progress","Not started"))) -> Not started
A13: CC3.4 | B13: Risk Assessment | C13: Identifies and assesses changes that could significantly impact internal control | D13: =COUNTIF('Control Matrix'!$J$2:$J$70,"*"&A13&"*") -> 4 | E13: =COUNTIFS('Control Matrix'!$J$2:$J$70,"*"&A13&"*",'Control Matrix'!$R$2:$R$70,"Implemented") -> 0 | F13: =IF(D13>0,"Covered","GAP") -> Covered | G13: =IF(D13=0,"GAP",IF(E13=D13,"Ready",IF(E13>0,"In progress","Not started"))) -> Not started
... A34: CC9.2 | B34: Risk Mitigation | C34: Assesses and manages risks associated with vendors and business partners | D34: =COUNTIF('Control Matrix'!$J$2:$J$70,"*"&A34&"*") -> 3 | E34: =COUNTIFS('Control Matrix'!$J$2:$J$70,"*"&A34&"*",'Control Matrix'!$R$2:$R$70,"Implemented") -> 0 | F34: =IF(D34>0,"Covered","GAP") -> Covered | G34: =IF(D34=0,"GAP",IF(E34=D34,"Ready",IF(E34>0,"In progress","Not started"))) -> Not started
A36: Mapped control IDs (static reference, generated at build):
A37: CC1.1 | B37: GOV-01, GOV-07, HR-02
A38: CC1.2 | B38: GOV-02
A39: CC1.3 | B39: GOV-03, GOV-04, HR-04
A40: CC1.4 | B40: HR-01, HR-03, HR-04
A41: CC1.5 | B41: HR-02, HR-04, HR-05
A42: CC2.1 | B42: GOV-04, GOV-08, CHG-06, INF-07, MON-01
A43: CC2.2 | B43: GOV-01, GOV-07, HR-02, HR-03
A44: CC2.3 | B44: GOV-06, GOV-07, VEN-02, IR-01, IR-02
A45: CC3.1 | B45: RSK-01, RSK-02
A46: CC3.2 | B46: RSK-01, INF-07
A47: CC3.3 | B47: RSK-01
A48: CC3.4 | B48: GOV-08, RSK-01, RSK-03, CHG-12
... A69: CC9.2 | B69: VEN-01, VEN-02, VEN-03

Sheet Integration Inventory
A1: Code | B1: Subsystem | C1: Category | D1: Example Tools (vendor-neutral) | E1: Your Tool | F1: Identity / Auth Integration | G1: Audit Log Export | H1: Integrates With | I1: Data Handled (Classification) | J1: Evidence Produced | K1: Key Controls | L1: System Owner
A2: SCM | B2: Source Control | C2: CI/CD | D2: e.g., GitHub, GitLab, Bitbucket | E2: GitHub Enterprise Cloud | F2: SAML/OIDC SSO via IdP + SCIM; enforce SSO for org | G2: Audit log streaming to SIEM (webhook / streaming API) | H2: CI, SEC, ITSM, IDP, SIEM | I2: Source code, IaC, pipeline definitions (Confidential) | J2: Rulesets, merged PR + review data, CODEOWNERS, secret-scanning alerts | K2: CHG-01, CHG-02, CHG-11, INF-06, IAM-01
A3: CI | B3: CI/CD Pipeline | C3: CI/CD | D3: e.g., GitHub Actions, GitLab CI, Jenkins, Argo CD | E3: GitHub Actions | F3: SSO via IdP; deploy via OIDC workload identity to cloud | G3: Run logs + audit events to SIEM; deployment records to evidence store | H3: SCM, REG, CLD, K8S, VAULT, SEC, ITSM | I3: Build artifacts, deploy metadata, secrets at runtime (Restricted) | J3: Pipeline run logs, gate results, deployment records (SHA->PR->run->digest) | K3: CHG-03 to CHG-07, CHG-10, CHG-11
A4: REG | B4: Artifact Registry | C4: CI/CD | D4: e.g., ECR, Artifact Registry, ACR, Harbor, JFrog | F4: Pull/push by workload identity; humans read-only via SSO | G4: Registry audit events to SIEM | H4: CI, K8S, SEC | I4: Container images, packages (Confidential) | J4: Image signatures, provenance attestations, scan results | K4: CHG-07, VUL-01, VUL-03
A5: CLD | B5: Cloud Platform | C5: Infrastructure | D5: e.g., AWS, Azure, GCP | F5: Federated SSO from IdP to roles; no IAM users; OIDC for CI | G5: Control-plane audit logs (e.g., CloudTrail / Activity Log / Audit Logs) org-wide to log archive + SIEM | H5: IAC, CI, K8S, SIEM, BKP, VAULT, SEC | I5: Production customer data (Restricted) | J5: IAM exports, config/asset inventory, encryption settings, audit logs | K5: IAM-05, CHG-05, CHG-08, INF-01 to INF-05, BCP-04
A6: IAC | B6: IaC / Config Mgmt | C6: Infrastructure | D6: e.g., Terraform/OpenTofu, Pulumi, CloudFormation, Ansible | F6: Executed only by pipeline identity; state in encrypted remote backend | G6: Plan/apply logs archived by pipeline | H6: SCM, CI, CLD | I6: Infrastructure definitions, state files (Restricted) | J6: Plan outputs, apply logs, policy-as-code results | K6: CHG-10, INF-01, INF-03, IAM-05
